2025-05-24 01:45:08,170 - pyswarms.single.global_best - INFO - Optimize for 30 iters with {'c1': 0.5, 'c2': 0.3, 'w': 0.9}
2025-05-24 01:46:34,019 - pyswarms.single.global_best - INFO - Optimization finished | best cost: -0.5799168152109329, best pos: [28.76816189  2.40062836]
2025-05-24 01:46:34,024 - pyswarms.single.global_best - INFO - Optimize for 30 iters with {'c1': 0.5, 'c2': 0.3, 'w': 0.9}
2025-05-24 01:46:50,551 - pyswarms.single.global_best - INFO - Optimization finished | best cost: -0.5600118835412954, best pos: [3.21919767 0.01922862]
2025-05-24 03:55:18,110 - pyswarms.single.global_best - INFO - Optimize for 30 iters with {'c1': 0.5, 'c2': 0.3, 'w': 0.9}
2025-05-24 03:56:58,453 - pyswarms.single.global_best - INFO - Optimization finished | best cost: -0.5799168152109329, best pos: [28.76816189  2.40062836]
2025-05-24 03:56:58,469 - pyswarms.single.global_best - INFO - Optimize for 30 iters with {'c1': 0.5, 'c2': 0.3, 'w': 0.9}
2025-05-24 03:57:16,038 - pyswarms.single.global_best - INFO - Optimization finished | best cost: -0.5600118835412954, best pos: [3.21919767 0.01922862]
2025-05-24 05:25:48,262 - pygad.pygad - ERROR - 
All the 3 fits failed.
It is very likely that your model is misconfigured.
You can try to debug the error by setting error_score='raise'.

Below are more details about the failures:
--------------------------------------------------------------------------------
3 fits failed with the following error:
Traceback (most recent call last):
  File "c:\Users\arau7\AppData\Local\Programs\Python\Python312\Lib\site-packages\pandas\core\indexes\base.py", line 3805, in get_loc
    return self._engine.get_loc(casted_key)
           ^^^^^^^^^^^^^^^^^^^^^^^^^^^^^^^^
  File "index.pyx", line 167, in pandas._libs.index.IndexEngine.get_loc
  File "index.pyx", line 196, in pandas._libs.index.IndexEngine.get_loc
  File "pandas\\_libs\\hashtable_class_helper.pxi", line 7081, in pandas._libs.hashtable.PyObjectHashTable.get_item
  File "pandas\\_libs\\hashtable_class_helper.pxi", line 7089, in pandas._libs.hashtable.PyObjectHashTable.get_item
KeyError: 'Объект1_Угол'

The above exception was the direct cause of the following exception:

Traceback (most recent call last):
  File "c:\Users\arau7\AppData\Local\Programs\Python\Python312\Lib\site-packages\sklearn\utils\_indexing.py", line 364, in _get_column_indices
    col_idx = all_columns.get_loc(col)
              ^^^^^^^^^^^^^^^^^^^^^^^^
  File "c:\Users\arau7\AppData\Local\Programs\Python\Python312\Lib\site-packages\pandas\core\indexes\base.py", line 3812, in get_loc
    raise KeyError(key) from err
KeyError: 'Объект1_Угол'

The above exception was the direct cause of the following exception:

Traceback (most recent call last):
  File "c:\Users\arau7\AppData\Local\Programs\Python\Python312\Lib\site-packages\sklearn\model_selection\_validation.py", line 866, in _fit_and_score
    estimator.fit(X_train, y_train, **fit_params)
  File "c:\Users\arau7\AppData\Local\Programs\Python\Python312\Lib\site-packages\sklearn\base.py", line 1389, in wrapper
    return fit_method(estimator, *args, **kwargs)
           ^^^^^^^^^^^^^^^^^^^^^^^^^^^^^^^^^^^^^^
  File "c:\Users\arau7\AppData\Local\Programs\Python\Python312\Lib\site-packages\sklearn\pipeline.py", line 654, in fit
    Xt = self._fit(X, y, routed_params, raw_params=params)
         ^^^^^^^^^^^^^^^^^^^^^^^^^^^^^^^^^^^^^^^^^^^^^^^^^
  File "c:\Users\arau7\AppData\Local\Programs\Python\Python312\Lib\site-packages\sklearn\pipeline.py", line 588, in _fit
    X, fitted_transformer = fit_transform_one_cached(
                            ^^^^^^^^^^^^^^^^^^^^^^^^^
  File "c:\Users\arau7\AppData\Local\Programs\Python\Python312\Lib\site-packages\joblib\memory.py", line 326, in __call__
    return self.func(*args, **kwargs)
           ^^^^^^^^^^^^^^^^^^^^^^^^^^
  File "c:\Users\arau7\AppData\Local\Programs\Python\Python312\Lib\site-packages\sklearn\pipeline.py", line 1551, in _fit_transform_one
    res = transformer.fit_transform(X, y, **params.get("fit_transform", {}))
          ^^^^^^^^^^^^^^^^^^^^^^^^^^^^^^^^^^^^^^^^^^^^^^^^^^^^^^^^^^^^^^^^^^
  File "c:\Users\arau7\AppData\Local\Programs\Python\Python312\Lib\site-packages\sklearn\utils\_set_output.py", line 319, in wrapped
    data_to_wrap = f(self, X, *args, **kwargs)
                   ^^^^^^^^^^^^^^^^^^^^^^^^^^^
  File "c:\Users\arau7\AppData\Local\Programs\Python\Python312\Lib\site-packages\sklearn\base.py", line 1389, in wrapper
    return fit_method(estimator, *args, **kwargs)
           ^^^^^^^^^^^^^^^^^^^^^^^^^^^^^^^^^^^^^^
  File "c:\Users\arau7\AppData\Local\Programs\Python\Python312\Lib\site-packages\sklearn\compose\_column_transformer.py", line 993, in fit_transform
    self._validate_column_callables(X)
  File "c:\Users\arau7\AppData\Local\Programs\Python\Python312\Lib\site-packages\sklearn\compose\_column_transformer.py", line 552, in _validate_column_callables
    transformer_to_input_indices[name] = _get_column_indices(X, columns)
                                         ^^^^^^^^^^^^^^^^^^^^^^^^^^^^^^^
  File "c:\Users\arau7\AppData\Local\Programs\Python\Python312\Lib\site-packages\sklearn\utils\_indexing.py", line 372, in _get_column_indices
    raise ValueError("A given column is not a column of the dataframe") from e
ValueError: A given column is not a column of the dataframe
Traceback (most recent call last):
  File "c:\Users\arau7\AppData\Local\Programs\Python\Python312\Lib\site-packages\pygad\pygad.py", line 1697, in cal_pop_fitness
    fitness = self.fitness_func(self, sol, sol_idx)
              ^^^^^^^^^^^^^^^^^^^^^^^^^^^^^^^^^^^^^
  File "C:\Users\arau7\AppData\Local\Temp\ipykernel_16240\2927508631.py", line 29, in fitness_rf
    return evaluate(model, X, y)
           ^^^^^^^^^^^^^^^^^^^^^
  File "C:\Users\arau7\AppData\Local\Temp\ipykernel_16240\2927508631.py", line 20, in evaluate
    return cross_val_score(pipeline, X, y, cv=3, scoring='accuracy').mean()
           ^^^^^^^^^^^^^^^^^^^^^^^^^^^^^^^^^^^^^^^^^^^^^^^^^^^^^^^^^
  File "c:\Users\arau7\AppData\Local\Programs\Python\Python312\Lib\site-packages\sklearn\utils\_param_validation.py", line 216, in wrapper
    return func(*args, **kwargs)
           ^^^^^^^^^^^^^^^^^^^^^
  File "c:\Users\arau7\AppData\Local\Programs\Python\Python312\Lib\site-packages\sklearn\model_selection\_validation.py", line 684, in cross_val_score
    cv_results = cross_validate(
                 ^^^^^^^^^^^^^^^
  File "c:\Users\arau7\AppData\Local\Programs\Python\Python312\Lib\site-packages\sklearn\utils\_param_validation.py", line 216, in wrapper
    return func(*args, **kwargs)
           ^^^^^^^^^^^^^^^^^^^^^
  File "c:\Users\arau7\AppData\Local\Programs\Python\Python312\Lib\site-packages\sklearn\model_selection\_validation.py", line 431, in cross_validate
    _warn_or_raise_about_fit_failures(results, error_score)
  File "c:\Users\arau7\AppData\Local\Programs\Python\Python312\Lib\site-packages\sklearn\model_selection\_validation.py", line 517, in _warn_or_raise_about_fit_failures
    raise ValueError(all_fits_failed_message)
ValueError: 
All the 3 fits failed.
It is very likely that your model is misconfigured.
You can try to debug the error by setting error_score='raise'.

Below are more details about the failures:
--------------------------------------------------------------------------------
3 fits failed with the following error:
Traceback (most recent call last):
  File "c:\Users\arau7\AppData\Local\Programs\Python\Python312\Lib\site-packages\pandas\core\indexes\base.py", line 3805, in get_loc
    return self._engine.get_loc(casted_key)
           ^^^^^^^^^^^^^^^^^^^^^^^^^^^^^^^^
  File "index.pyx", line 167, in pandas._libs.index.IndexEngine.get_loc
  File "index.pyx", line 196, in pandas._libs.index.IndexEngine.get_loc
  File "pandas\\_libs\\hashtable_class_helper.pxi", line 7081, in pandas._libs.hashtable.PyObjectHashTable.get_item
  File "pandas\\_libs\\hashtable_class_helper.pxi", line 7089, in pandas._libs.hashtable.PyObjectHashTable.get_item
KeyError: 'Объект1_Угол'

The above exception was the direct cause of the following exception:

Traceback (most recent call last):
  File "c:\Users\arau7\AppData\Local\Programs\Python\Python312\Lib\site-packages\sklearn\utils\_indexing.py", line 364, in _get_column_indices
    col_idx = all_columns.get_loc(col)
              ^^^^^^^^^^^^^^^^^^^^^^^^
  File "c:\Users\arau7\AppData\Local\Programs\Python\Python312\Lib\site-packages\pandas\core\indexes\base.py", line 3812, in get_loc
    raise KeyError(key) from err
KeyError: 'Объект1_Угол'

The above exception was the direct cause of the following exception:

Traceback (most recent call last):
  File "c:\Users\arau7\AppData\Local\Programs\Python\Python312\Lib\site-packages\sklearn\model_selection\_validation.py", line 866, in _fit_and_score
    estimator.fit(X_train, y_train, **fit_params)
  File "c:\Users\arau7\AppData\Local\Programs\Python\Python312\Lib\site-packages\sklearn\base.py", line 1389, in wrapper
    return fit_method(estimator, *args, **kwargs)
           ^^^^^^^^^^^^^^^^^^^^^^^^^^^^^^^^^^^^^^
  File "c:\Users\arau7\AppData\Local\Programs\Python\Python312\Lib\site-packages\sklearn\pipeline.py", line 654, in fit
    Xt = self._fit(X, y, routed_params, raw_params=params)
         ^^^^^^^^^^^^^^^^^^^^^^^^^^^^^^^^^^^^^^^^^^^^^^^^^
  File "c:\Users\arau7\AppData\Local\Programs\Python\Python312\Lib\site-packages\sklearn\pipeline.py", line 588, in _fit
    X, fitted_transformer = fit_transform_one_cached(
                            ^^^^^^^^^^^^^^^^^^^^^^^^^
  File "c:\Users\arau7\AppData\Local\Programs\Python\Python312\Lib\site-packages\joblib\memory.py", line 326, in __call__
    return self.func(*args, **kwargs)
           ^^^^^^^^^^^^^^^^^^^^^^^^^^
  File "c:\Users\arau7\AppData\Local\Programs\Python\Python312\Lib\site-packages\sklearn\pipeline.py", line 1551, in _fit_transform_one
    res = transformer.fit_transform(X, y, **params.get("fit_transform", {}))
          ^^^^^^^^^^^^^^^^^^^^^^^^^^^^^^^^^^^^^^^^^^^^^^^^^^^^^^^^^^^^^^^^^^
  File "c:\Users\arau7\AppData\Local\Programs\Python\Python312\Lib\site-packages\sklearn\utils\_set_output.py", line 319, in wrapped
    data_to_wrap = f(self, X, *args, **kwargs)
                   ^^^^^^^^^^^^^^^^^^^^^^^^^^^
  File "c:\Users\arau7\AppData\Local\Programs\Python\Python312\Lib\site-packages\sklearn\base.py", line 1389, in wrapper
    return fit_method(estimator, *args, **kwargs)
           ^^^^^^^^^^^^^^^^^^^^^^^^^^^^^^^^^^^^^^
  File "c:\Users\arau7\AppData\Local\Programs\Python\Python312\Lib\site-packages\sklearn\compose\_column_transformer.py", line 993, in fit_transform
    self._validate_column_callables(X)
  File "c:\Users\arau7\AppData\Local\Programs\Python\Python312\Lib\site-packages\sklearn\compose\_column_transformer.py", line 552, in _validate_column_callables
    transformer_to_input_indices[name] = _get_column_indices(X, columns)
                                         ^^^^^^^^^^^^^^^^^^^^^^^^^^^^^^^
  File "c:\Users\arau7\AppData\Local\Programs\Python\Python312\Lib\site-packages\sklearn\utils\_indexing.py", line 372, in _get_column_indices
    raise ValueError("A given column is not a column of the dataframe") from e
ValueError: A given column is not a column of the dataframe

2025-05-24 05:25:48,282 - pygad.pygad - ERROR - 
All the 3 fits failed.
It is very likely that your model is misconfigured.
You can try to debug the error by setting error_score='raise'.

Below are more details about the failures:
--------------------------------------------------------------------------------
3 fits failed with the following error:
Traceback (most recent call last):
  File "c:\Users\arau7\AppData\Local\Programs\Python\Python312\Lib\site-packages\pandas\core\indexes\base.py", line 3805, in get_loc
    return self._engine.get_loc(casted_key)
           ^^^^^^^^^^^^^^^^^^^^^^^^^^^^^^^^
  File "index.pyx", line 167, in pandas._libs.index.IndexEngine.get_loc
  File "index.pyx", line 196, in pandas._libs.index.IndexEngine.get_loc
  File "pandas\\_libs\\hashtable_class_helper.pxi", line 7081, in pandas._libs.hashtable.PyObjectHashTable.get_item
  File "pandas\\_libs\\hashtable_class_helper.pxi", line 7089, in pandas._libs.hashtable.PyObjectHashTable.get_item
KeyError: 'Объект1_Угол'

The above exception was the direct cause of the following exception:

Traceback (most recent call last):
  File "c:\Users\arau7\AppData\Local\Programs\Python\Python312\Lib\site-packages\sklearn\utils\_indexing.py", line 364, in _get_column_indices
    col_idx = all_columns.get_loc(col)
              ^^^^^^^^^^^^^^^^^^^^^^^^
  File "c:\Users\arau7\AppData\Local\Programs\Python\Python312\Lib\site-packages\pandas\core\indexes\base.py", line 3812, in get_loc
    raise KeyError(key) from err
KeyError: 'Объект1_Угол'

The above exception was the direct cause of the following exception:

Traceback (most recent call last):
  File "c:\Users\arau7\AppData\Local\Programs\Python\Python312\Lib\site-packages\sklearn\model_selection\_validation.py", line 866, in _fit_and_score
    estimator.fit(X_train, y_train, **fit_params)
  File "c:\Users\arau7\AppData\Local\Programs\Python\Python312\Lib\site-packages\sklearn\base.py", line 1389, in wrapper
    return fit_method(estimator, *args, **kwargs)
           ^^^^^^^^^^^^^^^^^^^^^^^^^^^^^^^^^^^^^^
  File "c:\Users\arau7\AppData\Local\Programs\Python\Python312\Lib\site-packages\sklearn\pipeline.py", line 654, in fit
    Xt = self._fit(X, y, routed_params, raw_params=params)
         ^^^^^^^^^^^^^^^^^^^^^^^^^^^^^^^^^^^^^^^^^^^^^^^^^
  File "c:\Users\arau7\AppData\Local\Programs\Python\Python312\Lib\site-packages\sklearn\pipeline.py", line 588, in _fit
    X, fitted_transformer = fit_transform_one_cached(
                            ^^^^^^^^^^^^^^^^^^^^^^^^^
  File "c:\Users\arau7\AppData\Local\Programs\Python\Python312\Lib\site-packages\joblib\memory.py", line 326, in __call__
    return self.func(*args, **kwargs)
           ^^^^^^^^^^^^^^^^^^^^^^^^^^
  File "c:\Users\arau7\AppData\Local\Programs\Python\Python312\Lib\site-packages\sklearn\pipeline.py", line 1551, in _fit_transform_one
    res = transformer.fit_transform(X, y, **params.get("fit_transform", {}))
          ^^^^^^^^^^^^^^^^^^^^^^^^^^^^^^^^^^^^^^^^^^^^^^^^^^^^^^^^^^^^^^^^^^
  File "c:\Users\arau7\AppData\Local\Programs\Python\Python312\Lib\site-packages\sklearn\utils\_set_output.py", line 319, in wrapped
    data_to_wrap = f(self, X, *args, **kwargs)
                   ^^^^^^^^^^^^^^^^^^^^^^^^^^^
  File "c:\Users\arau7\AppData\Local\Programs\Python\Python312\Lib\site-packages\sklearn\base.py", line 1389, in wrapper
    return fit_method(estimator, *args, **kwargs)
           ^^^^^^^^^^^^^^^^^^^^^^^^^^^^^^^^^^^^^^
  File "c:\Users\arau7\AppData\Local\Programs\Python\Python312\Lib\site-packages\sklearn\compose\_column_transformer.py", line 993, in fit_transform
    self._validate_column_callables(X)
  File "c:\Users\arau7\AppData\Local\Programs\Python\Python312\Lib\site-packages\sklearn\compose\_column_transformer.py", line 552, in _validate_column_callables
    transformer_to_input_indices[name] = _get_column_indices(X, columns)
                                         ^^^^^^^^^^^^^^^^^^^^^^^^^^^^^^^
  File "c:\Users\arau7\AppData\Local\Programs\Python\Python312\Lib\site-packages\sklearn\utils\_indexing.py", line 372, in _get_column_indices
    raise ValueError("A given column is not a column of the dataframe") from e
ValueError: A given column is not a column of the dataframe
Traceback (most recent call last):
  File "c:\Users\arau7\AppData\Local\Programs\Python\Python312\Lib\site-packages\pygad\pygad.py", line 1903, in run
    self.last_generation_fitness = self.cal_pop_fitness()
                                   ^^^^^^^^^^^^^^^^^^^^^^
  File "c:\Users\arau7\AppData\Local\Programs\Python\Python312\Lib\site-packages\pygad\pygad.py", line 1860, in cal_pop_fitness
    raise ex
  File "c:\Users\arau7\AppData\Local\Programs\Python\Python312\Lib\site-packages\pygad\pygad.py", line 1697, in cal_pop_fitness
    fitness = self.fitness_func(self, sol, sol_idx)
              ^^^^^^^^^^^^^^^^^^^^^^^^^^^^^^^^^^^^^
  File "C:\Users\arau7\AppData\Local\Temp\ipykernel_16240\2927508631.py", line 29, in fitness_rf
    return evaluate(model, X, y)
           ^^^^^^^^^^^^^^^^^^^^^
  File "C:\Users\arau7\AppData\Local\Temp\ipykernel_16240\2927508631.py", line 20, in evaluate
    return cross_val_score(pipeline, X, y, cv=3, scoring='accuracy').mean()
           ^^^^^^^^^^^^^^^^^^^^^^^^^^^^^^^^^^^^^^^^^^^^^^^^^^^^^^^^^
  File "c:\Users\arau7\AppData\Local\Programs\Python\Python312\Lib\site-packages\sklearn\utils\_param_validation.py", line 216, in wrapper
    return func(*args, **kwargs)
           ^^^^^^^^^^^^^^^^^^^^^
  File "c:\Users\arau7\AppData\Local\Programs\Python\Python312\Lib\site-packages\sklearn\model_selection\_validation.py", line 684, in cross_val_score
    cv_results = cross_validate(
                 ^^^^^^^^^^^^^^^
  File "c:\Users\arau7\AppData\Local\Programs\Python\Python312\Lib\site-packages\sklearn\utils\_param_validation.py", line 216, in wrapper
    return func(*args, **kwargs)
           ^^^^^^^^^^^^^^^^^^^^^
  File "c:\Users\arau7\AppData\Local\Programs\Python\Python312\Lib\site-packages\sklearn\model_selection\_validation.py", line 431, in cross_validate
    _warn_or_raise_about_fit_failures(results, error_score)
  File "c:\Users\arau7\AppData\Local\Programs\Python\Python312\Lib\site-packages\sklearn\model_selection\_validation.py", line 517, in _warn_or_raise_about_fit_failures
    raise ValueError(all_fits_failed_message)
ValueError: 
All the 3 fits failed.
It is very likely that your model is misconfigured.
You can try to debug the error by setting error_score='raise'.

Below are more details about the failures:
--------------------------------------------------------------------------------
3 fits failed with the following error:
Traceback (most recent call last):
  File "c:\Users\arau7\AppData\Local\Programs\Python\Python312\Lib\site-packages\pandas\core\indexes\base.py", line 3805, in get_loc
    return self._engine.get_loc(casted_key)
           ^^^^^^^^^^^^^^^^^^^^^^^^^^^^^^^^
  File "index.pyx", line 167, in pandas._libs.index.IndexEngine.get_loc
  File "index.pyx", line 196, in pandas._libs.index.IndexEngine.get_loc
  File "pandas\\_libs\\hashtable_class_helper.pxi", line 7081, in pandas._libs.hashtable.PyObjectHashTable.get_item
  File "pandas\\_libs\\hashtable_class_helper.pxi", line 7089, in pandas._libs.hashtable.PyObjectHashTable.get_item
KeyError: 'Объект1_Угол'

The above exception was the direct cause of the following exception:

Traceback (most recent call last):
  File "c:\Users\arau7\AppData\Local\Programs\Python\Python312\Lib\site-packages\sklearn\utils\_indexing.py", line 364, in _get_column_indices
    col_idx = all_columns.get_loc(col)
              ^^^^^^^^^^^^^^^^^^^^^^^^
  File "c:\Users\arau7\AppData\Local\Programs\Python\Python312\Lib\site-packages\pandas\core\indexes\base.py", line 3812, in get_loc
    raise KeyError(key) from err
KeyError: 'Объект1_Угол'

The above exception was the direct cause of the following exception:

Traceback (most recent call last):
  File "c:\Users\arau7\AppData\Local\Programs\Python\Python312\Lib\site-packages\sklearn\model_selection\_validation.py", line 866, in _fit_and_score
    estimator.fit(X_train, y_train, **fit_params)
  File "c:\Users\arau7\AppData\Local\Programs\Python\Python312\Lib\site-packages\sklearn\base.py", line 1389, in wrapper
    return fit_method(estimator, *args, **kwargs)
           ^^^^^^^^^^^^^^^^^^^^^^^^^^^^^^^^^^^^^^
  File "c:\Users\arau7\AppData\Local\Programs\Python\Python312\Lib\site-packages\sklearn\pipeline.py", line 654, in fit
    Xt = self._fit(X, y, routed_params, raw_params=params)
         ^^^^^^^^^^^^^^^^^^^^^^^^^^^^^^^^^^^^^^^^^^^^^^^^^
  File "c:\Users\arau7\AppData\Local\Programs\Python\Python312\Lib\site-packages\sklearn\pipeline.py", line 588, in _fit
    X, fitted_transformer = fit_transform_one_cached(
                            ^^^^^^^^^^^^^^^^^^^^^^^^^
  File "c:\Users\arau7\AppData\Local\Programs\Python\Python312\Lib\site-packages\joblib\memory.py", line 326, in __call__
    return self.func(*args, **kwargs)
           ^^^^^^^^^^^^^^^^^^^^^^^^^^
  File "c:\Users\arau7\AppData\Local\Programs\Python\Python312\Lib\site-packages\sklearn\pipeline.py", line 1551, in _fit_transform_one
    res = transformer.fit_transform(X, y, **params.get("fit_transform", {}))
          ^^^^^^^^^^^^^^^^^^^^^^^^^^^^^^^^^^^^^^^^^^^^^^^^^^^^^^^^^^^^^^^^^^
  File "c:\Users\arau7\AppData\Local\Programs\Python\Python312\Lib\site-packages\sklearn\utils\_set_output.py", line 319, in wrapped
    data_to_wrap = f(self, X, *args, **kwargs)
                   ^^^^^^^^^^^^^^^^^^^^^^^^^^^
  File "c:\Users\arau7\AppData\Local\Programs\Python\Python312\Lib\site-packages\sklearn\base.py", line 1389, in wrapper
    return fit_method(estimator, *args, **kwargs)
           ^^^^^^^^^^^^^^^^^^^^^^^^^^^^^^^^^^^^^^
  File "c:\Users\arau7\AppData\Local\Programs\Python\Python312\Lib\site-packages\sklearn\compose\_column_transformer.py", line 993, in fit_transform
    self._validate_column_callables(X)
  File "c:\Users\arau7\AppData\Local\Programs\Python\Python312\Lib\site-packages\sklearn\compose\_column_transformer.py", line 552, in _validate_column_callables
    transformer_to_input_indices[name] = _get_column_indices(X, columns)
                                         ^^^^^^^^^^^^^^^^^^^^^^^^^^^^^^^
  File "c:\Users\arau7\AppData\Local\Programs\Python\Python312\Lib\site-packages\sklearn\utils\_indexing.py", line 372, in _get_column_indices
    raise ValueError("A given column is not a column of the dataframe") from e
ValueError: A given column is not a column of the dataframe

2025-05-24 05:26:22,101 - pygad.pygad - ERROR - 
All the 3 fits failed.
It is very likely that your model is misconfigured.
You can try to debug the error by setting error_score='raise'.

Below are more details about the failures:
--------------------------------------------------------------------------------
3 fits failed with the following error:
Traceback (most recent call last):
  File "c:\Users\arau7\AppData\Local\Programs\Python\Python312\Lib\site-packages\pandas\core\indexes\base.py", line 3805, in get_loc
    return self._engine.get_loc(casted_key)
           ^^^^^^^^^^^^^^^^^^^^^^^^^^^^^^^^
  File "index.pyx", line 167, in pandas._libs.index.IndexEngine.get_loc
  File "index.pyx", line 196, in pandas._libs.index.IndexEngine.get_loc
  File "pandas\\_libs\\hashtable_class_helper.pxi", line 7081, in pandas._libs.hashtable.PyObjectHashTable.get_item
  File "pandas\\_libs\\hashtable_class_helper.pxi", line 7089, in pandas._libs.hashtable.PyObjectHashTable.get_item
KeyError: 'Объект1_Угол'

The above exception was the direct cause of the following exception:

Traceback (most recent call last):
  File "c:\Users\arau7\AppData\Local\Programs\Python\Python312\Lib\site-packages\sklearn\utils\_indexing.py", line 364, in _get_column_indices
    col_idx = all_columns.get_loc(col)
              ^^^^^^^^^^^^^^^^^^^^^^^^
  File "c:\Users\arau7\AppData\Local\Programs\Python\Python312\Lib\site-packages\pandas\core\indexes\base.py", line 3812, in get_loc
    raise KeyError(key) from err
KeyError: 'Объект1_Угол'

The above exception was the direct cause of the following exception:

Traceback (most recent call last):
  File "c:\Users\arau7\AppData\Local\Programs\Python\Python312\Lib\site-packages\sklearn\model_selection\_validation.py", line 866, in _fit_and_score
    estimator.fit(X_train, y_train, **fit_params)
  File "c:\Users\arau7\AppData\Local\Programs\Python\Python312\Lib\site-packages\sklearn\base.py", line 1389, in wrapper
    return fit_method(estimator, *args, **kwargs)
           ^^^^^^^^^^^^^^^^^^^^^^^^^^^^^^^^^^^^^^
  File "c:\Users\arau7\AppData\Local\Programs\Python\Python312\Lib\site-packages\sklearn\pipeline.py", line 654, in fit
    Xt = self._fit(X, y, routed_params, raw_params=params)
         ^^^^^^^^^^^^^^^^^^^^^^^^^^^^^^^^^^^^^^^^^^^^^^^^^
  File "c:\Users\arau7\AppData\Local\Programs\Python\Python312\Lib\site-packages\sklearn\pipeline.py", line 588, in _fit
    X, fitted_transformer = fit_transform_one_cached(
                            ^^^^^^^^^^^^^^^^^^^^^^^^^
  File "c:\Users\arau7\AppData\Local\Programs\Python\Python312\Lib\site-packages\joblib\memory.py", line 326, in __call__
    return self.func(*args, **kwargs)
           ^^^^^^^^^^^^^^^^^^^^^^^^^^
  File "c:\Users\arau7\AppData\Local\Programs\Python\Python312\Lib\site-packages\sklearn\pipeline.py", line 1551, in _fit_transform_one
    res = transformer.fit_transform(X, y, **params.get("fit_transform", {}))
          ^^^^^^^^^^^^^^^^^^^^^^^^^^^^^^^^^^^^^^^^^^^^^^^^^^^^^^^^^^^^^^^^^^
  File "c:\Users\arau7\AppData\Local\Programs\Python\Python312\Lib\site-packages\sklearn\utils\_set_output.py", line 319, in wrapped
    data_to_wrap = f(self, X, *args, **kwargs)
                   ^^^^^^^^^^^^^^^^^^^^^^^^^^^
  File "c:\Users\arau7\AppData\Local\Programs\Python\Python312\Lib\site-packages\sklearn\base.py", line 1389, in wrapper
    return fit_method(estimator, *args, **kwargs)
           ^^^^^^^^^^^^^^^^^^^^^^^^^^^^^^^^^^^^^^
  File "c:\Users\arau7\AppData\Local\Programs\Python\Python312\Lib\site-packages\sklearn\compose\_column_transformer.py", line 993, in fit_transform
    self._validate_column_callables(X)
  File "c:\Users\arau7\AppData\Local\Programs\Python\Python312\Lib\site-packages\sklearn\compose\_column_transformer.py", line 552, in _validate_column_callables
    transformer_to_input_indices[name] = _get_column_indices(X, columns)
                                         ^^^^^^^^^^^^^^^^^^^^^^^^^^^^^^^
  File "c:\Users\arau7\AppData\Local\Programs\Python\Python312\Lib\site-packages\sklearn\utils\_indexing.py", line 372, in _get_column_indices
    raise ValueError("A given column is not a column of the dataframe") from e
ValueError: A given column is not a column of the dataframe
Traceback (most recent call last):
  File "c:\Users\arau7\AppData\Local\Programs\Python\Python312\Lib\site-packages\pygad\pygad.py", line 1697, in cal_pop_fitness
    fitness = self.fitness_func(self, sol, sol_idx)
              ^^^^^^^^^^^^^^^^^^^^^^^^^^^^^^^^^^^^^
  File "C:\Users\arau7\AppData\Local\Temp\ipykernel_16240\2927508631.py", line 29, in fitness_rf
    return evaluate(model, X, y)
           ^^^^^^^^^^^^^^^^^^^^^
  File "C:\Users\arau7\AppData\Local\Temp\ipykernel_16240\2927508631.py", line 20, in evaluate
    return cross_val_score(pipeline, X, y, cv=3, scoring='accuracy').mean()
           ^^^^^^^^^^^^^^^^^^^^^^^^^^^^^^^^^^^^^^^^^^^^^^^^^^^^^^^^^
  File "c:\Users\arau7\AppData\Local\Programs\Python\Python312\Lib\site-packages\sklearn\utils\_param_validation.py", line 216, in wrapper
    return func(*args, **kwargs)
           ^^^^^^^^^^^^^^^^^^^^^
  File "c:\Users\arau7\AppData\Local\Programs\Python\Python312\Lib\site-packages\sklearn\model_selection\_validation.py", line 684, in cross_val_score
    cv_results = cross_validate(
                 ^^^^^^^^^^^^^^^
  File "c:\Users\arau7\AppData\Local\Programs\Python\Python312\Lib\site-packages\sklearn\utils\_param_validation.py", line 216, in wrapper
    return func(*args, **kwargs)
           ^^^^^^^^^^^^^^^^^^^^^
  File "c:\Users\arau7\AppData\Local\Programs\Python\Python312\Lib\site-packages\sklearn\model_selection\_validation.py", line 431, in cross_validate
    _warn_or_raise_about_fit_failures(results, error_score)
  File "c:\Users\arau7\AppData\Local\Programs\Python\Python312\Lib\site-packages\sklearn\model_selection\_validation.py", line 517, in _warn_or_raise_about_fit_failures
    raise ValueError(all_fits_failed_message)
ValueError: 
All the 3 fits failed.
It is very likely that your model is misconfigured.
You can try to debug the error by setting error_score='raise'.

Below are more details about the failures:
--------------------------------------------------------------------------------
3 fits failed with the following error:
Traceback (most recent call last):
  File "c:\Users\arau7\AppData\Local\Programs\Python\Python312\Lib\site-packages\pandas\core\indexes\base.py", line 3805, in get_loc
    return self._engine.get_loc(casted_key)
           ^^^^^^^^^^^^^^^^^^^^^^^^^^^^^^^^
  File "index.pyx", line 167, in pandas._libs.index.IndexEngine.get_loc
  File "index.pyx", line 196, in pandas._libs.index.IndexEngine.get_loc
  File "pandas\\_libs\\hashtable_class_helper.pxi", line 7081, in pandas._libs.hashtable.PyObjectHashTable.get_item
  File "pandas\\_libs\\hashtable_class_helper.pxi", line 7089, in pandas._libs.hashtable.PyObjectHashTable.get_item
KeyError: 'Объект1_Угол'

The above exception was the direct cause of the following exception:

Traceback (most recent call last):
  File "c:\Users\arau7\AppData\Local\Programs\Python\Python312\Lib\site-packages\sklearn\utils\_indexing.py", line 364, in _get_column_indices
    col_idx = all_columns.get_loc(col)
              ^^^^^^^^^^^^^^^^^^^^^^^^
  File "c:\Users\arau7\AppData\Local\Programs\Python\Python312\Lib\site-packages\pandas\core\indexes\base.py", line 3812, in get_loc
    raise KeyError(key) from err
KeyError: 'Объект1_Угол'

The above exception was the direct cause of the following exception:

Traceback (most recent call last):
  File "c:\Users\arau7\AppData\Local\Programs\Python\Python312\Lib\site-packages\sklearn\model_selection\_validation.py", line 866, in _fit_and_score
    estimator.fit(X_train, y_train, **fit_params)
  File "c:\Users\arau7\AppData\Local\Programs\Python\Python312\Lib\site-packages\sklearn\base.py", line 1389, in wrapper
    return fit_method(estimator, *args, **kwargs)
           ^^^^^^^^^^^^^^^^^^^^^^^^^^^^^^^^^^^^^^
  File "c:\Users\arau7\AppData\Local\Programs\Python\Python312\Lib\site-packages\sklearn\pipeline.py", line 654, in fit
    Xt = self._fit(X, y, routed_params, raw_params=params)
         ^^^^^^^^^^^^^^^^^^^^^^^^^^^^^^^^^^^^^^^^^^^^^^^^^
  File "c:\Users\arau7\AppData\Local\Programs\Python\Python312\Lib\site-packages\sklearn\pipeline.py", line 588, in _fit
    X, fitted_transformer = fit_transform_one_cached(
                            ^^^^^^^^^^^^^^^^^^^^^^^^^
  File "c:\Users\arau7\AppData\Local\Programs\Python\Python312\Lib\site-packages\joblib\memory.py", line 326, in __call__
    return self.func(*args, **kwargs)
           ^^^^^^^^^^^^^^^^^^^^^^^^^^
  File "c:\Users\arau7\AppData\Local\Programs\Python\Python312\Lib\site-packages\sklearn\pipeline.py", line 1551, in _fit_transform_one
    res = transformer.fit_transform(X, y, **params.get("fit_transform", {}))
          ^^^^^^^^^^^^^^^^^^^^^^^^^^^^^^^^^^^^^^^^^^^^^^^^^^^^^^^^^^^^^^^^^^
  File "c:\Users\arau7\AppData\Local\Programs\Python\Python312\Lib\site-packages\sklearn\utils\_set_output.py", line 319, in wrapped
    data_to_wrap = f(self, X, *args, **kwargs)
                   ^^^^^^^^^^^^^^^^^^^^^^^^^^^
  File "c:\Users\arau7\AppData\Local\Programs\Python\Python312\Lib\site-packages\sklearn\base.py", line 1389, in wrapper
    return fit_method(estimator, *args, **kwargs)
           ^^^^^^^^^^^^^^^^^^^^^^^^^^^^^^^^^^^^^^
  File "c:\Users\arau7\AppData\Local\Programs\Python\Python312\Lib\site-packages\sklearn\compose\_column_transformer.py", line 993, in fit_transform
    self._validate_column_callables(X)
  File "c:\Users\arau7\AppData\Local\Programs\Python\Python312\Lib\site-packages\sklearn\compose\_column_transformer.py", line 552, in _validate_column_callables
    transformer_to_input_indices[name] = _get_column_indices(X, columns)
                                         ^^^^^^^^^^^^^^^^^^^^^^^^^^^^^^^
  File "c:\Users\arau7\AppData\Local\Programs\Python\Python312\Lib\site-packages\sklearn\utils\_indexing.py", line 372, in _get_column_indices
    raise ValueError("A given column is not a column of the dataframe") from e
ValueError: A given column is not a column of the dataframe

2025-05-24 05:26:22,103 - pygad.pygad - ERROR - 
All the 3 fits failed.
It is very likely that your model is misconfigured.
You can try to debug the error by setting error_score='raise'.

Below are more details about the failures:
--------------------------------------------------------------------------------
3 fits failed with the following error:
Traceback (most recent call last):
  File "c:\Users\arau7\AppData\Local\Programs\Python\Python312\Lib\site-packages\pandas\core\indexes\base.py", line 3805, in get_loc
    return self._engine.get_loc(casted_key)
           ^^^^^^^^^^^^^^^^^^^^^^^^^^^^^^^^
  File "index.pyx", line 167, in pandas._libs.index.IndexEngine.get_loc
  File "index.pyx", line 196, in pandas._libs.index.IndexEngine.get_loc
  File "pandas\\_libs\\hashtable_class_helper.pxi", line 7081, in pandas._libs.hashtable.PyObjectHashTable.get_item
  File "pandas\\_libs\\hashtable_class_helper.pxi", line 7089, in pandas._libs.hashtable.PyObjectHashTable.get_item
KeyError: 'Объект1_Угол'

The above exception was the direct cause of the following exception:

Traceback (most recent call last):
  File "c:\Users\arau7\AppData\Local\Programs\Python\Python312\Lib\site-packages\sklearn\utils\_indexing.py", line 364, in _get_column_indices
    col_idx = all_columns.get_loc(col)
              ^^^^^^^^^^^^^^^^^^^^^^^^
  File "c:\Users\arau7\AppData\Local\Programs\Python\Python312\Lib\site-packages\pandas\core\indexes\base.py", line 3812, in get_loc
    raise KeyError(key) from err
KeyError: 'Объект1_Угол'

The above exception was the direct cause of the following exception:

Traceback (most recent call last):
  File "c:\Users\arau7\AppData\Local\Programs\Python\Python312\Lib\site-packages\sklearn\model_selection\_validation.py", line 866, in _fit_and_score
    estimator.fit(X_train, y_train, **fit_params)
  File "c:\Users\arau7\AppData\Local\Programs\Python\Python312\Lib\site-packages\sklearn\base.py", line 1389, in wrapper
    return fit_method(estimator, *args, **kwargs)
           ^^^^^^^^^^^^^^^^^^^^^^^^^^^^^^^^^^^^^^
  File "c:\Users\arau7\AppData\Local\Programs\Python\Python312\Lib\site-packages\sklearn\pipeline.py", line 654, in fit
    Xt = self._fit(X, y, routed_params, raw_params=params)
         ^^^^^^^^^^^^^^^^^^^^^^^^^^^^^^^^^^^^^^^^^^^^^^^^^
  File "c:\Users\arau7\AppData\Local\Programs\Python\Python312\Lib\site-packages\sklearn\pipeline.py", line 588, in _fit
    X, fitted_transformer = fit_transform_one_cached(
                            ^^^^^^^^^^^^^^^^^^^^^^^^^
  File "c:\Users\arau7\AppData\Local\Programs\Python\Python312\Lib\site-packages\joblib\memory.py", line 326, in __call__
    return self.func(*args, **kwargs)
           ^^^^^^^^^^^^^^^^^^^^^^^^^^
  File "c:\Users\arau7\AppData\Local\Programs\Python\Python312\Lib\site-packages\sklearn\pipeline.py", line 1551, in _fit_transform_one
    res = transformer.fit_transform(X, y, **params.get("fit_transform", {}))
          ^^^^^^^^^^^^^^^^^^^^^^^^^^^^^^^^^^^^^^^^^^^^^^^^^^^^^^^^^^^^^^^^^^
  File "c:\Users\arau7\AppData\Local\Programs\Python\Python312\Lib\site-packages\sklearn\utils\_set_output.py", line 319, in wrapped
    data_to_wrap = f(self, X, *args, **kwargs)
                   ^^^^^^^^^^^^^^^^^^^^^^^^^^^
  File "c:\Users\arau7\AppData\Local\Programs\Python\Python312\Lib\site-packages\sklearn\base.py", line 1389, in wrapper
    return fit_method(estimator, *args, **kwargs)
           ^^^^^^^^^^^^^^^^^^^^^^^^^^^^^^^^^^^^^^
  File "c:\Users\arau7\AppData\Local\Programs\Python\Python312\Lib\site-packages\sklearn\compose\_column_transformer.py", line 993, in fit_transform
    self._validate_column_callables(X)
  File "c:\Users\arau7\AppData\Local\Programs\Python\Python312\Lib\site-packages\sklearn\compose\_column_transformer.py", line 552, in _validate_column_callables
    transformer_to_input_indices[name] = _get_column_indices(X, columns)
                                         ^^^^^^^^^^^^^^^^^^^^^^^^^^^^^^^
  File "c:\Users\arau7\AppData\Local\Programs\Python\Python312\Lib\site-packages\sklearn\utils\_indexing.py", line 372, in _get_column_indices
    raise ValueError("A given column is not a column of the dataframe") from e
ValueError: A given column is not a column of the dataframe
Traceback (most recent call last):
  File "c:\Users\arau7\AppData\Local\Programs\Python\Python312\Lib\site-packages\pygad\pygad.py", line 1903, in run
    self.last_generation_fitness = self.cal_pop_fitness()
                                   ^^^^^^^^^^^^^^^^^^^^^^
  File "c:\Users\arau7\AppData\Local\Programs\Python\Python312\Lib\site-packages\pygad\pygad.py", line 1860, in cal_pop_fitness
    raise ex
  File "c:\Users\arau7\AppData\Local\Programs\Python\Python312\Lib\site-packages\pygad\pygad.py", line 1697, in cal_pop_fitness
    fitness = self.fitness_func(self, sol, sol_idx)
              ^^^^^^^^^^^^^^^^^^^^^^^^^^^^^^^^^^^^^
  File "C:\Users\arau7\AppData\Local\Temp\ipykernel_16240\2927508631.py", line 29, in fitness_rf
    return evaluate(model, X, y)
           ^^^^^^^^^^^^^^^^^^^^^
  File "C:\Users\arau7\AppData\Local\Temp\ipykernel_16240\2927508631.py", line 20, in evaluate
    return cross_val_score(pipeline, X, y, cv=3, scoring='accuracy').mean()
           ^^^^^^^^^^^^^^^^^^^^^^^^^^^^^^^^^^^^^^^^^^^^^^^^^^^^^^^^^
  File "c:\Users\arau7\AppData\Local\Programs\Python\Python312\Lib\site-packages\sklearn\utils\_param_validation.py", line 216, in wrapper
    return func(*args, **kwargs)
           ^^^^^^^^^^^^^^^^^^^^^
  File "c:\Users\arau7\AppData\Local\Programs\Python\Python312\Lib\site-packages\sklearn\model_selection\_validation.py", line 684, in cross_val_score
    cv_results = cross_validate(
                 ^^^^^^^^^^^^^^^
  File "c:\Users\arau7\AppData\Local\Programs\Python\Python312\Lib\site-packages\sklearn\utils\_param_validation.py", line 216, in wrapper
    return func(*args, **kwargs)
           ^^^^^^^^^^^^^^^^^^^^^
  File "c:\Users\arau7\AppData\Local\Programs\Python\Python312\Lib\site-packages\sklearn\model_selection\_validation.py", line 431, in cross_validate
    _warn_or_raise_about_fit_failures(results, error_score)
  File "c:\Users\arau7\AppData\Local\Programs\Python\Python312\Lib\site-packages\sklearn\model_selection\_validation.py", line 517, in _warn_or_raise_about_fit_failures
    raise ValueError(all_fits_failed_message)
ValueError: 
All the 3 fits failed.
It is very likely that your model is misconfigured.
You can try to debug the error by setting error_score='raise'.

Below are more details about the failures:
--------------------------------------------------------------------------------
3 fits failed with the following error:
Traceback (most recent call last):
  File "c:\Users\arau7\AppData\Local\Programs\Python\Python312\Lib\site-packages\pandas\core\indexes\base.py", line 3805, in get_loc
    return self._engine.get_loc(casted_key)
           ^^^^^^^^^^^^^^^^^^^^^^^^^^^^^^^^
  File "index.pyx", line 167, in pandas._libs.index.IndexEngine.get_loc
  File "index.pyx", line 196, in pandas._libs.index.IndexEngine.get_loc
  File "pandas\\_libs\\hashtable_class_helper.pxi", line 7081, in pandas._libs.hashtable.PyObjectHashTable.get_item
  File "pandas\\_libs\\hashtable_class_helper.pxi", line 7089, in pandas._libs.hashtable.PyObjectHashTable.get_item
KeyError: 'Объект1_Угол'

The above exception was the direct cause of the following exception:

Traceback (most recent call last):
  File "c:\Users\arau7\AppData\Local\Programs\Python\Python312\Lib\site-packages\sklearn\utils\_indexing.py", line 364, in _get_column_indices
    col_idx = all_columns.get_loc(col)
              ^^^^^^^^^^^^^^^^^^^^^^^^
  File "c:\Users\arau7\AppData\Local\Programs\Python\Python312\Lib\site-packages\pandas\core\indexes\base.py", line 3812, in get_loc
    raise KeyError(key) from err
KeyError: 'Объект1_Угол'

The above exception was the direct cause of the following exception:

Traceback (most recent call last):
  File "c:\Users\arau7\AppData\Local\Programs\Python\Python312\Lib\site-packages\sklearn\model_selection\_validation.py", line 866, in _fit_and_score
    estimator.fit(X_train, y_train, **fit_params)
  File "c:\Users\arau7\AppData\Local\Programs\Python\Python312\Lib\site-packages\sklearn\base.py", line 1389, in wrapper
    return fit_method(estimator, *args, **kwargs)
           ^^^^^^^^^^^^^^^^^^^^^^^^^^^^^^^^^^^^^^
  File "c:\Users\arau7\AppData\Local\Programs\Python\Python312\Lib\site-packages\sklearn\pipeline.py", line 654, in fit
    Xt = self._fit(X, y, routed_params, raw_params=params)
         ^^^^^^^^^^^^^^^^^^^^^^^^^^^^^^^^^^^^^^^^^^^^^^^^^
  File "c:\Users\arau7\AppData\Local\Programs\Python\Python312\Lib\site-packages\sklearn\pipeline.py", line 588, in _fit
    X, fitted_transformer = fit_transform_one_cached(
                            ^^^^^^^^^^^^^^^^^^^^^^^^^
  File "c:\Users\arau7\AppData\Local\Programs\Python\Python312\Lib\site-packages\joblib\memory.py", line 326, in __call__
    return self.func(*args, **kwargs)
           ^^^^^^^^^^^^^^^^^^^^^^^^^^
  File "c:\Users\arau7\AppData\Local\Programs\Python\Python312\Lib\site-packages\sklearn\pipeline.py", line 1551, in _fit_transform_one
    res = transformer.fit_transform(X, y, **params.get("fit_transform", {}))
          ^^^^^^^^^^^^^^^^^^^^^^^^^^^^^^^^^^^^^^^^^^^^^^^^^^^^^^^^^^^^^^^^^^
  File "c:\Users\arau7\AppData\Local\Programs\Python\Python312\Lib\site-packages\sklearn\utils\_set_output.py", line 319, in wrapped
    data_to_wrap = f(self, X, *args, **kwargs)
                   ^^^^^^^^^^^^^^^^^^^^^^^^^^^
  File "c:\Users\arau7\AppData\Local\Programs\Python\Python312\Lib\site-packages\sklearn\base.py", line 1389, in wrapper
    return fit_method(estimator, *args, **kwargs)
           ^^^^^^^^^^^^^^^^^^^^^^^^^^^^^^^^^^^^^^
  File "c:\Users\arau7\AppData\Local\Programs\Python\Python312\Lib\site-packages\sklearn\compose\_column_transformer.py", line 993, in fit_transform
    self._validate_column_callables(X)
  File "c:\Users\arau7\AppData\Local\Programs\Python\Python312\Lib\site-packages\sklearn\compose\_column_transformer.py", line 552, in _validate_column_callables
    transformer_to_input_indices[name] = _get_column_indices(X, columns)
                                         ^^^^^^^^^^^^^^^^^^^^^^^^^^^^^^^
  File "c:\Users\arau7\AppData\Local\Programs\Python\Python312\Lib\site-packages\sklearn\utils\_indexing.py", line 372, in _get_column_indices
    raise ValueError("A given column is not a column of the dataframe") from e
ValueError: A given column is not a column of the dataframe

2025-05-24 05:31:20,864 - pygad.pygad - ERROR - In PyGAD 2.20.0, the fitness function must accept 3 parameters:
1) The instance of the 'pygad.GA' class.
2) A solution to calculate its fitness value.
3) The solution's index within the population.

The passed fitness function named 'fitness_func_rf' accepts 2 parameter(s).
Traceback (most recent call last):
  File "c:\Users\arau7\AppData\Local\Programs\Python\Python312\Lib\site-packages\pygad\pygad.py", line 947, in __init__
    raise ValueError(f"In PyGAD 2.20.0, the fitness function must accept 3 parameters:\n1) The instance of the 'pygad.GA' class.\n2) A solution to calculate its fitness value.\n3) The solution's index within the population.\n\nThe passed fitness function named '{fitness_func.__code__.co_name}' accepts {fitness_func.__code__.co_argcount} parameter(s).")
ValueError: In PyGAD 2.20.0, the fitness function must accept 3 parameters:
1) The instance of the 'pygad.GA' class.
2) A solution to calculate its fitness value.
3) The solution's index within the population.

The passed fitness function named 'fitness_func_rf' accepts 2 parameter(s).
2025-05-24 05:31:58,852 - pygad.pygad - ERROR - In PyGAD 2.20.0, the fitness function must accept 3 parameters:
1) The instance of the 'pygad.GA' class.
2) A solution to calculate its fitness value.
3) The solution's index within the population.

The passed fitness function named 'fitness_func_rf' accepts 2 parameter(s).
Traceback (most recent call last):
  File "c:\Users\arau7\AppData\Local\Programs\Python\Python312\Lib\site-packages\pygad\pygad.py", line 947, in __init__
    raise ValueError(f"In PyGAD 2.20.0, the fitness function must accept 3 parameters:\n1) The instance of the 'pygad.GA' class.\n2) A solution to calculate its fitness value.\n3) The solution's index within the population.\n\nThe passed fitness function named '{fitness_func.__code__.co_name}' accepts {fitness_func.__code__.co_argcount} parameter(s).")
ValueError: In PyGAD 2.20.0, the fitness function must accept 3 parameters:
1) The instance of the 'pygad.GA' class.
2) A solution to calculate its fitness value.
3) The solution's index within the population.

The passed fitness function named 'fitness_func_rf' accepts 2 parameter(s).
2025-05-24 05:32:09,338 - pyswarms.single.global_best - INFO - Optimize for 20 iters with {'c1': 0.5, 'c2': 0.3, 'w': 0.9}
2025-05-24 05:32:11,119 - pyswarms.single.global_best - INFO - Optimization finished | best cost: -0.6153846153846154, best pos: [0.00242055]
2025-05-24 06:00:02,502 - pyswarms.single.global_best - INFO - Optimize for 100 iters with {'c1': 0.5, 'c2': 0.3, 'w': 0.9}
2025-05-24 06:00:10,504 - pyswarms.single.global_best - INFO - Optimization finished | best cost: -0.6923076923076923, best pos: [1.38843165]
2025-05-24 06:10:49,071 - pyswarms.single.global_best - INFO - Optimize for 50 iters with {'c1': 0.5, 'c2': 0.3, 'w': 0.9}
2025-05-24 06:10:57,277 - pyswarms.single.global_best - INFO - Optimization finished | best cost: 0.375, best pos: [0.27527977 0.5170812  0.50944181]
2025-05-24 06:32:18,188 - pyswarms.single.global_best - INFO - Optimize for 50 iters with {'c1': 0.5, 'c2': 0.3, 'w': 0.9}
2025-05-24 06:32:26,564 - pyswarms.single.global_best - INFO - Optimization finished | best cost: 0.4285714285714286, best pos: [1.89064265 0.59565333 0.91312168]
2025-05-24 06:35:32,586 - pyswarms.single.global_best - INFO - Optimize for 50 iters with {'c1': 0.5, 'c2': 0.3, 'w': 0.9}
2025-05-24 06:35:40,442 - pyswarms.single.global_best - INFO - Optimization finished | best cost: 0.4, best pos: [1.8590788  0.86514236 0.43051577]
